<?xml version="1.0"?>
<robot>
  <!-- ReelRbtx Reel-->
  <link name="reel_wheel_link">
    <visual>
      <origin xyz="0 0 0" rpy="${PI/2} 0 0"/>
      <geometry>
        <mesh filename="package://jackal_description/meshes/jackal-wheel.stl"/>
      </geometry>
      <material name="black" />
    </visual>
    <collision>
      <origin xyz="0 0 0" rpy="${PI/2} 0 0"/>
      <geometry>
        <cylinder radius="${wheel_radius}" length="${wheel_width}"/>
      </geometry>
    </collision>
    <inertial>
      <origin xyz="0 0 0" rpy="0 0 0"/>
      <mass value="0.477"/>
      <inertia
          ixx="0.0013" ixy="0" ixz="0"
          iyy="0.0024" iyz="0"
          izz="0.0013"/>
    </inertial>
  </link>

  <gazebo reference="reel_wheel_link">
    <material>Gazebo/DarkGrey</material>
  </gazebo>

  <joint name="reel_wheel" type="continuous">
    <parent link="chassis_link"/>
    <child link="reel_wheel_link" />
    <origin xyz="-0.1 0 0.2" rpy="0 0 0"/>
    <axis xyz="0 1 0" />
  </joint>

  <transmission name="reel_wheel_trans">
    <type>transmission_interface/SimpleTransmission</type>
    <joint name="reel_wheel">
      <hardwareInterface>PositionJointInterface</hardwareInterface>
    </joint>
    <actuator name="reel_actuator">
      <mechanicalReduction>1</mechanicalReduction>
    </actuator>
  </transmission>
  <!-- End ReelRbtx Reel -->
</robot>